import pytest

from quart import Quart
from quart.debug import traceback_response


@pytest.mark.asyncio
async def test_debug() -> None:
    app = Quart(__name__)
    async with app.test_request_context("/"):
        try:
            raise Exception("Unique error")
        except Exception:
            response = await traceback_response()

    assert response.status_code == 500
    assert b"Unique error" in (await response.get_data())  # type: ignore
